<?xml version="1.0"?>
<robot xmlns:xacro="http://www.ros.org/wiki/xacro" name="diablo">
  <xacro:macro name="description">
    <!-- <link name="world"/> -->
    <link name="base_footprint">
      <inertial>
        <mass value="0.0001"/>
        <origin xyz="0 0 0" rpy="0 0 0"/>
        <inertia ixx="1e-6" ixy="0" ixz="0" iyy="1e-6" iyz="0" izz="1e-6"/>
      </inertial>
    </link>

    
    <link name="base_link">
      <inertial>
        <origin xyz="0.020452 3.5457E-06 0.01871" rpy="0 0 0" />
        <mass value="13.2" />
        <inertia ixx="0.061855" ixy="-2.6029E-05" ixz="0.00081082" iyy="0.036934" iyz="-1.7269E-05" izz="0.071232" />
      </inertial>
      <visual>
        <origin xyz="0 0 0" rpy="0 0 0" />
        <geometry>
          <mesh filename="file://$(find diablo_env_ros)/meshes/base_link.STL" />
        </geometry>
        <material name="black"/>
      </visual>
      <collision>
        <origin xyz="0 0 0" rpy="0 0 0" />
        <geometry>
          <box size="0.47 0.3 0.19"/>
          <!-- <mesh filename="file://$(find diablo_env_ros)/meshes/base_link.STL" /> -->
        </geometry>
      </collision>
    </link>
    <!-- <joint name="base_link_joint" type="fixed">
      <origin rpy="0 0 0" xyz="0 0 0.41"/>
      <parent link="world"/>
      <child link="base_link"/>
      <axis xyz="0 0 0"/>
    </joint> -->

    <joint name="base_footprint_joint" type="fixed">
      <parent link="base_footprint"/>
      <child link="base_link"/>
      <origin xyz="0 0 0.4925" rpy="0 0 0"/>
    </joint>


    
    <link name="lidar_frame">
      <visual>
        <origin rpy="0 0 0" xyz="0 0 0"/>
        <geometry>
          <box size="0.01 0.01 0.01"/>
        </geometry>
        <material name="green"/>
      </visual>
      <!-- <collision>
        <origin rpy="0 0 0" xyz="0 0 0"/>
        <geometry>
          <box size="0.01 0.01 0.01"/>
        </geometry>
      </collision> -->
      <inertial>
        <mass value="0.001"/>
        <inertia ixx="0.00001" ixy="0.0" ixz="0.0" iyy="0.00001" iyz="0.0" izz="0.00001"/>
      </inertial>
    </link>

    <joint name="lidar_frame_joint" type="fixed">
      <parent link="base_link"/>      <!-- or whichever link is below -->
      <child link="lidar_frame"/>
      <origin xyz="0 0 0" rpy="0 1.5708 0"/> <!-- adjust height so it’s just below robot -->
    </joint>




    <link name="spad">
    </link>
    <joint name="joint_spad" type="fixed">
      <origin xyz="0.24052 -0.0019 0.064455" rpy="2.199 0 1.5708" />
      <parent link="base_link" />
      <child link="spad" />
      <axis xyz="0 0 0" />
    </joint>


    <link name="spad1">
    </link>
    <joint name="joint_spad1" type="fixed">
      <origin xyz="0.21953 -0.0019 -0.030142" rpy="2.632 0 1.5708" />
      <parent link="base_link" />
      <child link="spad1" />
      <axis xyz="0 0 0" />
    </joint>


    <link name="left_camera">
    </link>
    <joint name="joint_left_camera" type="fixed">
      <origin xyz="0.23416 0.075 0.04036" rpy="1.5708 0 1.5708" />
      <parent link="base_link" />
      <child link="left_camera" />
      <axis xyz="0 0 0" />
    </joint>


    <link name="ch201">
    </link>
    <joint name="joint_ch201" type="fixed">
      <origin xyz="0.23782 0 0.018636" rpy="1.1693 0 1.5708" />
      <parent link="base_link" />
      <child link="ch201" />
      <axis xyz="0 0 0" />
    </joint>


    <link name="right_camara">
    </link>
    <joint name="joint_right_camera" type="fixed">
      <origin xyz="0.23416 -0.075001 0.04036" rpy="1.5708 0 1.5708" />
      <parent link="base_link" />
      <child link="right_camara" />
      <axis xyz="0 0 0" />
    </joint>
    

    <link name="imu_link">
      <inertial>
        <mass value="0.001"/>
        <origin rpy="0 0 0" xyz="0 0 0"/>
        <inertia ixx="0.0001" ixy="0" ixz="0" iyy="0.0001" iyz="0" izz="0.0001"/>
      </inertial>
      <visual>
        <origin rpy="0 0 0" xyz="0 0 0"/>
        <geometry>
          <box size="0.001 0.001 0.001"/>
        </geometry>
        <material name="red"/>
      </visual>
      <!-- <collision>
        <origin rpy="0 0 0" xyz="0 0 0"/>
        <geometry>
          <box size=".001 .001 .001"/>
        </geometry>
      </collision> -->
    </link>

    <joint name="imu_joint" type="fixed">
      <parent link="base_link"/>
      <child link="imu_link"/>
      <origin rpy="0 0 0" xyz="0 0 0"/>
    </joint>

    <link name="left_leg_1">
      <inertial>
        <origin xyz="0.0016025 5.0253E-05 0.000638" rpy="0 0 0" />
        <mass value="2.064" />
        <inertia ixx="0.0043044" ixy="-1.3538E-07" ixz="8.054E-05" iyy="0.0029982" iyz="-1.5446E-06" izz="0.0022703" />
      </inertial>
      <visual>
        <origin xyz="0 0 0" rpy="0 0 0" />
        <geometry>
          <mesh filename="file://$(find diablo_env_ros)/meshes/left_leg_1.STL" />
        </geometry>
        <material name="blue"/>
      </visual>
      <!-- <collision>
        <origin xyz="0 0 0" rpy="0 0 0" />
        <geometry>
          <mesh filename="file://$(find diablo_env_ros)/meshes/left_leg_1.STL" />
        </geometry>
      </collision> -->
    </link>
    <joint name="joint_left_leg_1" type="revolute">
      <origin xyz="0 0.0895 0" rpy="1.5708 0 1.5708" />
      <parent link="base_link" />
      <child link="left_leg_1" />
      <axis xyz="0 0 1" />
      <limit lower="-0.1" upper="0.1" effort="100" velocity="100" />
    </joint>

    <link name="left_leg_2">
      <inertial>
        <origin xyz="0.021763 0.0019069 -0.027868" rpy="0 0 0" />
        <mass value="3.0984" />
        <inertia ixx="0.0029784" ixy="-9.6332E-05" ixz="7.878E-05" iyy="0.0064836" iyz="4.3691E-06" izz="0.0088353" />
      </inertial>
      <visual>
        <origin xyz="0 0 0" rpy="0 0 0" />
        <geometry>
          <mesh filename="file://$(find diablo_env_ros)/meshes/left_leg_2.STL" />
        </geometry>
        <material name="green"/>
      </visual>
      <!-- <collision>
        <origin xyz="0 0 0" rpy="0 0 0" />
        <geometry>
          <mesh filename="file://$(find diablo_env_ros)/meshes/left_leg_2.STL" />
        </geometry>
      </collision> -->
    </link>
    <joint name="joint_left_leg_2" type="revolute">
      <origin xyz="0.1426 0 0" rpy="-1.5708 0 -1.5708" />
      <parent link="left_leg_1" />
      <child link="left_leg_2" />
      <axis xyz="0 0 1" />
      <limit lower="-1.919862" upper="3.490659" effort="100" velocity="100" />
    </joint>

    <link name="left_leg_3">
      <inertial>
        <origin xyz="0.095348 0.011698 0.001838" rpy="0 0 0" />
        <mass value="0.57244" />
        <inertia ixx="0.00030595" ixy="0.00035537" ixz="-0.00011764" iyy="0.0032009" iyz="1.129E-05" izz="0.0034209" />
      </inertial>
      <visual>
        <origin xyz="0 0 0" rpy="0 0 0" />
        <geometry>
          <mesh filename="file://$(find diablo_env_ros)/meshes/left_leg_3.STL" />
        </geometry>
        <material name="grey"/>
      </visual>
      <collision>
        <origin xyz="0.131 0 0" rpy="0 0 0" />
        <geometry>
          <box size="0.2 0.07 0.05"/>
          <!-- <mesh filename="file://$(find diablo_env_ros)/meshes/left_leg_3.STL" /> -->
        </geometry>
      </collision>
    </link>
    <joint name="joint_left_leg_3" type="revolute">
      <origin xyz="0.2 0 0" rpy="0 0 0" />
      <parent link="left_leg_2" />
      <child link="left_leg_3" />
      <axis xyz="0 0 1" />
      <limit lower="-2.670354" upper="-0.698132" effort="100" velocity="100" />
    </joint>

    <link name="left_leg_4">
      <inertial>
        <origin xyz="-2.267E-06 -1.6471E-06 -0.00095616" rpy="0 0 0" />
        <mass value="1.5094" />
        <inertia ixx="0.0035466" ixy="6.9816E-06" ixz="-2.3224E-07" iyy="0.0035053" iyz="-1.7712E-08" izz="0.0069049" />
      </inertial>
      <visual>
        <origin xyz="0 0 0" rpy="0 0 0" />
        <geometry>
          <!-- <cylinder length="0.034" radius="0.0925"/> -->
          <mesh filename="file://$(find diablo_env_ros)/meshes/left_leg_4.STL" />
        </geometry>
        <material name="silver"/>
      </visual>
      <collision>
        <origin xyz="0 0 0" rpy="0 0 0" />
        <geometry>
          <cylinder length="0.034" radius="0.0925"/>
          <!-- <mesh filename="file://$(find diablo_env_ros)/meshes/left_leg_4.STL" /> -->
        </geometry>
      </collision>
    </link>
    <joint name="joint_left_leg_4" type="revolute">
      <origin xyz="0.2 0 0.0514" rpy="0 0 0" />
      <parent link="left_leg_3" />
      <child link="left_leg_4" />
      <axis xyz="0 0 1" />
      <limit lower="-6.283185e4" upper="6.283185e4" effort="100" velocity="100" />
    </joint>

    <link name="right_leg_1">
      <inertial>
        <origin xyz="-0.0016025 5.0253E-05 0.00063801" rpy="0 0 0" />
        <mass value="2.064" />
        <inertia ixx="0.0043044" ixy="1.3538E-07" ixz="-8.054E-05" iyy="0.0029982" iyz="-1.5359E-06" izz="0.0022703" />
      </inertial>
      <visual>
        <origin xyz="0 0 0" rpy="0 0 0" />
        <geometry>
          <mesh filename="file://$(find diablo_env_ros)/meshes/right_leg_1.STL" />
        </geometry>
        <material name="blue"/>
      </visual>
      <!-- <collision>
        <origin xyz="0 0 0" rpy="0 0 0" />
        <geometry>
          <mesh filename="file://$(find diablo_env_ros)/meshes/right_leg_1.STL" />
        </geometry>
      </collision> -->
    </link>
    <joint name="joint_right_leg_1" type="revolute">
      <origin xyz="0 -0.0895 0" rpy="1.5708 0 1.5708" />
      <parent link="base_link" />
      <child link="right_leg_1" />
      <axis xyz="0 0 1" />
      <limit lower="-0.1" upper="0.1" effort="100" velocity="100" />
    </joint>

    <link name="right_leg_2">
      <inertial>
        <origin xyz="0.021763 0.0019065 0.027873" rpy="0 0 0" />
        <mass value="3.0987" />
        <inertia ixx="0.0029784" ixy="-9.6347E-05" ixz="-7.8776E-05" iyy="0.0064836" iyz="-4.3711E-06" izz="0.0088353" />
      </inertial>
      <visual>
        <origin xyz="0 0 0" rpy="0 0 0" />
        <geometry>
          <mesh filename="file://$(find diablo_env_ros)/meshes/right_leg_2.STL" />
        </geometry>
        <material name="green"/>
      </visual>
      <!-- <collision>
        <origin xyz="0 0 0" rpy="0 0 0" />
        <geometry>
          <mesh filename="file://$(find diablo_env_ros)/meshes/right_leg_2.STL" />
        </geometry>
      </collision> -->
    </link>
    <joint name="joint_right_leg_2" type="revolute">
      <origin xyz="-0.1426 0 0" rpy="-1.5708 0 -1.5708" />
      <parent link="right_leg_1" />
      <child link="right_leg_2" />
      <axis xyz="0 0 1" />
      <limit lower="-1.919862" upper="3.490659" effort="100" velocity="100" />
    </joint>

    <link name="right_leg_3">
      <inertial>
        <origin xyz="0.095348 0.011698 -0.001838" rpy="0 0 0" />
        <mass value="0.57244" />
        <inertia ixx="0.00030595" ixy="0.00035537" ixz="0.00011764" iyy="0.0032009" iyz="-1.129E-05" izz="0.0034209" />
      </inertial>
      <visual>
        <origin xyz="0 0 0" rpy="0 0 0" />
        <geometry>
          <mesh filename="file://$(find diablo_env_ros)/meshes/right_leg_3.STL" />
        </geometry>
        <material name="grey"/>
      </visual>
      <collision>
        <origin xyz="0.131 0 0" rpy="0 0 0" />
        <geometry>
          <box size="0.2 0.07 0.05"/>
          <!-- <mesh filename="file://$(find diablo_env_ros)/meshes/right_leg_3.STL" /> -->
        </geometry>
      </collision>
    </link>
    <joint name="joint_right_leg_3" type="revolute">
      <origin xyz="0.2 0 0" rpy="0 0 0" />
      <parent link="right_leg_2" />
      <child link="right_leg_3" />
      <axis xyz="0 0 1" />
      <limit lower="-2.670354" upper="-0.698132" effort="100" velocity="100" />
    </joint>
    
    <link name="right_leg_4">
      <inertial>
        <origin xyz="-2.3798E-06 -1.5854E-06 0.00095595" rpy="0 0 0" />
        <mass value="1.5094" />
        <inertia ixx="0.0035465" ixy="7.0548E-06" ixz="2.3146E-07" iyy="0.0035052" iyz="1.9287E-08" izz="0.0069047" />
      </inertial>
      <visual>
        <origin xyz="0 0 0" rpy="0 0 0" />
        <geometry>
          <mesh filename="file://$(find diablo_env_ros)/meshes/right_leg_4.STL" />
        </geometry>
        <material name="silver"/>
      </visual>
      <collision>
        <origin xyz="0 0 0" rpy="0 0 0" />
        <geometry>
          <cylinder length="0.034" radius="0.0925"/>
          <!-- <mesh filename="file://$(find diablo_env_ros)/meshes/right_leg_4.STL" /> -->
        </geometry>
      </collision>
    </link>
    <joint name="joint_right_leg_4" type="revolute">
      <origin xyz="0.2 0 -0.0514" rpy="0 0 0" />
      <parent link="right_leg_3" />
      <child link="right_leg_4" />
      <axis xyz="0 0 1" />
      <limit lower="-6.283185e4" upper="6.283185e4" effort="100" velocity="100" />
    </joint>
  </xacro:macro>
</robot>