<?xml version="1.0" ?>
<!-- =================================================================================== -->
<!-- |    This document was autogenerated by xacro from robot.xacro                    | -->
<!-- |    EDITING THIS FILE BY HAND IS NOT RECOMMENDED                                 | -->
<!-- =================================================================================== -->
<robot name="diablo">
  <material name="black">
    <color rgba="0.19607843137254902 0.19607843137254902 0.19607843137254902 1.0"/>
  </material>
  <material name="blue">
    <color rgba="0.0 0.0 0.8 1.0"/>
  </material>
  <material name="green">
    <color rgba="0.0 0.8 0.0 1.0"/>
  </material>
  <material name="grey">
    <color rgba="0.2 0.2 0.2 1.0"/>
  </material>
  <material name="silver">
    <color rgba="0.9137254901960784 0.9137254901960784 0.8470588235294118 1.0"/>
  </material>
  <material name="orange">
    <color rgba="1.0 0.4235294117647059 0.0392156862745098 1.0"/>
  </material>
  <material name="brown">
    <color rgba="0.8705882352941177 0.8117647058823529 0.7647058823529411 1.0"/>
  </material>
  <material name="red">
    <color rgba="0.8 0.0 0.0 1.0"/>
  </material>
  <material name="white">
    <color rgba="1.0 1.0 1.0 1.0"/>
  </material>
  <!-- <link name="world"/> -->
  <link name="base_footprint">
    <inertial>
      <mass value="0.0001"/>
      <origin rpy="0 0 0" xyz="0 0 0"/>
      <inertia ixx="1e-6" ixy="0" ixz="0" iyy="1e-6" iyz="0" izz="1e-6"/>
    </inertial>
  </link>
  <link name="base_link">
    <inertial>
      <origin rpy="0 0 0" xyz="-0.020452 3.5457E-06 0.01871"/>
      <mass value="13.2"/>
      <inertia ixx="0.061855" ixy="-2.6029E-05" ixz="0.00081082" iyy="0.036934" iyz="-1.7269E-05" izz="0.071232"/>
    </inertial>
    <visual>
      <origin rpy="0 0 0" xyz="0 0 0"/>
      <geometry>
        <mesh filename="file:///home/basanta-joshi/Desktop/virtual_environment/diablo_env_ros/install/diablo_env_ros/share/diablo_env_ros/meshes/base_link.STL"/>
      </geometry>
      <material name="black"/>
    </visual>
    <collision>
      <origin rpy="0 0 0" xyz="0 0 0"/>
      <geometry>
        <sphere radius="0.15"/>
        <!-- <box size="0.47 0.3 0.19"/> -->
        <!-- <mesh filename="file://$(find diablo_env_ros)/meshes/base_link.STL" /> -->
      </geometry>
    </collision>
  </link>
  <!-- <joint name="base_link_joint" type="fixed">
      <origin rpy="0 0 0" xyz="0 0 0.41"/>
      <parent link="world"/>
      <child link="base_link"/>
      <axis xyz="0 0 0"/>
    </joint> -->
  <joint name="base_footprint_joint" type="fixed">
    <parent link="base_footprint"/>
    <child link="base_link"/>
    <origin rpy="0 0 0" xyz="0 0 0.4925"/>
  </joint>
  <link name="lidar_frame">
    <visual>
      <origin rpy="0 0 0" xyz="0 0 0"/>
      <geometry>
        <box size="0.01 0.01 0.01"/>
      </geometry>
      <material name="green"/>
    </visual>
    <!-- <collision>
        <origin rpy="0 0 0" xyz="0 0 0"/>
        <geometry>
          <box size="0.01 0.01 0.01"/>
        </geometry>
      </collision> -->
    <inertial>
      <mass value="0.001"/>
      <inertia ixx="0.00001" ixy="0.0" ixz="0.0" iyy="0.00001" iyz="0.0" izz="0.00001"/>
    </inertial>
  </link>
  <joint name="lidar_frame_joint" type="fixed">
    <parent link="base_link"/>
    <!-- or whichever link is below -->
    <child link="lidar_frame"/>
    <origin rpy="0 1.5708 0" xyz="0 0 0"/>
    <!-- adjust height so it’s just below robot -->
  </joint>
  <!-- <link name="spad">
    </link>
    <joint name="joint_spad" type="fixed">
      <origin xyz="0.24052 -0.0019 0.064455" rpy="2.199 0 1.5708" />
      <parent link="base_link" />
      <child link="spad" />
      <axis xyz="0 0 0" />
    </joint>


    <link name="spad1">
    </link>
    <joint name="joint_spad1" type="fixed">
      <origin xyz="0.21953 -0.0019 -0.030142" rpy="2.632 0 1.5708" />
      <parent link="base_link" />
      <child link="spad1" />
      <axis xyz="0 0 0" />
    </joint>


    <link name="left_camera">
    </link>
    <joint name="joint_left_camera" type="fixed">
      <origin xyz="0.23416 0.075 0.04036" rpy="1.5708 0 1.5708" />
      <parent link="base_link" />
      <child link="left_camera" />
      <axis xyz="0 0 0" />
    </joint>


    <link name="ch201">
    </link>
    <joint name="joint_ch201" type="fixed">
      <origin xyz="0.23782 0 0.018636" rpy="1.1693 0 1.5708" />
      <parent link="base_link" />
      <child link="ch201" />
      <axis xyz="0 0 0" />
    </joint>


    <link name="right_camara">
    </link>
    <joint name="joint_right_camera" type="fixed">
      <origin xyz="0.23416 -0.075001 0.04036" rpy="1.5708 0 1.5708" />
      <parent link="base_link" />
      <child link="right_camara" />
      <axis xyz="0 0 0" />
    </joint> -->
  <link name="imu_link">
    <inertial>
      <mass value="0.001"/>
      <origin rpy="0 0 0" xyz="0 0 0"/>
      <inertia ixx="0.0001" ixy="0" ixz="0" iyy="0.0001" iyz="0" izz="0.0001"/>
    </inertial>
    <visual>
      <origin rpy="0 0 0" xyz="0 0 0"/>
      <geometry>
        <box size="0.001 0.001 0.001"/>
      </geometry>
      <material name="red"/>
    </visual>
    <!-- <collision>
        <origin rpy="0 0 0" xyz="0 0 0"/>
        <geometry>
          <box size=".001 .001 .001"/>
        </geometry>
      </collision> -->
  </link>
  <joint name="imu_joint" type="fixed">
    <parent link="base_link"/>
    <child link="imu_link"/>
    <origin rpy="0 0 0" xyz="0 0 0"/>
  </joint>
  <link name="left_leg_1">
    <inertial>
      <origin rpy="0 0 0" xyz="0.0016025 5.0253E-05 0.000638"/>
      <mass value="2.064"/>
      <inertia ixx="0.0043044" ixy="-1.3538E-07" ixz="8.054E-05" iyy="0.0029982" iyz="-1.5446E-06" izz="0.0022703"/>
    </inertial>
    <visual>
      <origin rpy="0 0 0" xyz="0 0 0"/>
      <geometry>
        <mesh filename="file:///home/basanta-joshi/Desktop/virtual_environment/diablo_env_ros/install/diablo_env_ros/share/diablo_env_ros/meshes/left_leg_1.STL"/>
      </geometry>
      <material name="blue"/>
    </visual>
    <!-- <collision>
        <origin xyz="0 0 0" rpy="0 0 0" />
        <geometry>
          <mesh filename="file://$(find diablo_env_ros)/meshes/left_leg_1.STL" />
        </geometry>
      </collision> -->
  </link>
  <joint name="joint_left_leg_1" type="revolute">
    <origin rpy="1.5708 0 1.5708" xyz="0 0.0895 0"/>
    <parent link="base_link"/>
    <child link="left_leg_1"/>
    <axis xyz="0 0 1"/>
    <limit effort="100" lower="-0.7854" upper="0.7854" velocity="100"/>
  </joint>
  <link name="left_leg_2">
    <inertial>
      <origin rpy="0 0 0" xyz="0.021763 0.0019069 -0.027868"/>
      <mass value="3.0984"/>
      <inertia ixx="0.0029784" ixy="-9.6332E-05" ixz="7.878E-05" iyy="0.0064836" iyz="4.3691E-06" izz="0.0088353"/>
    </inertial>
    <visual>
      <origin rpy="0 0 0" xyz="0 0 0"/>
      <geometry>
        <mesh filename="file:///home/basanta-joshi/Desktop/virtual_environment/diablo_env_ros/install/diablo_env_ros/share/diablo_env_ros/meshes/left_leg_2.STL"/>
      </geometry>
      <material name="green"/>
    </visual>
    <collision>
      <origin rpy="0 0 0" xyz="0.1 0 0"/>
      <geometry>
        <box size="0.2 0.07 0.05"/>
        <mesh filename="file:///home/basanta-joshi/Desktop/virtual_environment/diablo_env_ros/install/diablo_env_ros/share/diablo_env_ros/meshes/left_leg_2.STL"/>
      </geometry>
    </collision>
  </link>
  <joint name="joint_left_leg_2" type="revolute">
    <origin rpy="-1.5708 0 -1.5708" xyz="0.1426 0 0"/>
    <parent link="left_leg_1"/>
    <child link="left_leg_2"/>
    <axis xyz="0 0 1"/>
    <limit effort="100" lower="-1.919862" upper="3.490659" velocity="100"/>
  </joint>
  <link name="left_leg_3">
    <inertial>
      <origin rpy="0 0 0" xyz="0.095348 0.011698 0.001838"/>
      <mass value="0.57244"/>
      <inertia ixx="0.00030595" ixy="0.00035537" ixz="-0.00011764" iyy="0.0032009" iyz="1.129E-05" izz="0.0034209"/>
    </inertial>
    <visual>
      <origin rpy="0 0 0" xyz="0 0 0"/>
      <geometry>
        <mesh filename="file:///home/basanta-joshi/Desktop/virtual_environment/diablo_env_ros/install/diablo_env_ros/share/diablo_env_ros/meshes/left_leg_3.STL"/>
      </geometry>
      <material name="grey"/>
    </visual>
    <collision>
      <origin rpy="0 0 0" xyz="0.131 0 0"/>
      <geometry>
        <box size="0.2 0.07 0.05"/>
        <!-- <mesh filename="file://$(find diablo_env_ros)/meshes/left_leg_3.STL" /> -->
      </geometry>
    </collision>
  </link>
  <joint name="joint_left_leg_3" type="revolute">
    <origin rpy="0 0 0" xyz="0.2 0 0"/>
    <parent link="left_leg_2"/>
    <child link="left_leg_3"/>
    <axis xyz="0 0 1"/>
    <limit effort="100" lower="-2.670354" upper="-0.698132" velocity="100"/>
  </joint>
  <link name="left_leg_4">
    <inertial>
      <origin rpy="0 0 0" xyz="-2.267E-06 -1.6471E-06 -0.00095616"/>
      <mass value="1.5094"/>
      <inertia ixx="0.0035466" ixy="6.9816E-06" ixz="-2.3224E-07" iyy="0.0035053" iyz="-1.7712E-08" izz="0.0069049"/>
    </inertial>
    <visual>
      <origin rpy="0 0 0" xyz="0 0 0"/>
      <geometry>
        <box size="0.0925 0.0925 0.0925"/>
        <!-- <cylinder length="0.034" radius="0.0925"/> -->
        <!-- <mesh filename="file://$(find diablo_env_ros)/meshes/left_leg_4.STL" /> -->
      </geometry>
      <material name="silver"/>
    </visual>
    <collision>
      <origin rpy="0 0 0" xyz="0 0 0"/>
      <geometry>
        <box size="0.0925 0.0925 0.0925"/>
        <!-- <cylinder length="0.034" radius="0.0925"/> -->
        <!-- <mesh filename="file://$(find diablo_env_ros)/meshes/left_leg_4.STL" /> -->
      </geometry>
    </collision>
  </link>
  <joint name="joint_left_leg_4" type="revolute">
    <origin rpy="0 0 0" xyz="0.2 0 0.0514"/>
    <parent link="left_leg_3"/>
    <child link="left_leg_4"/>
    <axis xyz="0 0 1"/>
    <limit effort="100" lower="-6.283185e4" upper="6.283185e4" velocity="100"/>
  </joint>
  <link name="right_leg_1">
    <inertial>
      <origin rpy="0 0 0" xyz="-0.0016025 5.0253E-05 0.00063801"/>
      <mass value="2.064"/>
      <inertia ixx="0.0043044" ixy="1.3538E-07" ixz="-8.054E-05" iyy="0.0029982" iyz="-1.5359E-06" izz="0.0022703"/>
    </inertial>
    <visual>
      <origin rpy="0 0 0" xyz="0 0 0"/>
      <geometry>
        <mesh filename="file:///home/basanta-joshi/Desktop/virtual_environment/diablo_env_ros/install/diablo_env_ros/share/diablo_env_ros/meshes/right_leg_1.STL"/>
      </geometry>
      <material name="blue"/>
    </visual>
    <!-- <collision>
        <origin xyz="0 0 0" rpy="0 0 0" />
        <geometry>
          <mesh filename="file://$(find diablo_env_ros)/meshes/right_leg_1.STL" />
        </geometry>
      </collision> -->
  </link>
  <joint name="joint_right_leg_1" type="revolute">
    <origin rpy="1.5708 0 1.5708" xyz="0 -0.0895 0"/>
    <parent link="base_link"/>
    <child link="right_leg_1"/>
    <axis xyz="0 0 1"/>
    <limit effort="100" lower="-0.1" upper="0.1" velocity="100"/>
  </joint>
  <link name="right_leg_2">
    <inertial>
      <origin rpy="0 0 0" xyz="0.021763 0.0019065 0.027873"/>
      <mass value="3.0987"/>
      <inertia ixx="0.0029784" ixy="-9.6347E-05" ixz="-7.8776E-05" iyy="0.0064836" iyz="-4.3711E-06" izz="0.0088353"/>
    </inertial>
    <visual>
      <origin rpy="0 0 0" xyz="0 0 0"/>
      <geometry>
        <mesh filename="file:///home/basanta-joshi/Desktop/virtual_environment/diablo_env_ros/install/diablo_env_ros/share/diablo_env_ros/meshes/right_leg_2.STL"/>
      </geometry>
      <material name="green"/>
    </visual>
    <collision>
      <origin rpy="0 0 0" xyz="0.1 0 0"/>
      <geometry>
        <box size="0.2 0.07 0.05"/>
        <mesh filename="file:///home/basanta-joshi/Desktop/virtual_environment/diablo_env_ros/install/diablo_env_ros/share/diablo_env_ros/meshes/right_leg_2.STL"/>
      </geometry>
    </collision>
  </link>
  <joint name="joint_right_leg_2" type="revolute">
    <origin rpy="-1.5708 0 -1.5708" xyz="-0.1426 0 0"/>
    <parent link="right_leg_1"/>
    <child link="right_leg_2"/>
    <axis xyz="0 0 1"/>
    <limit effort="100" lower="-1.919862" upper="3.490659" velocity="100"/>
  </joint>
  <link name="right_leg_3">
    <inertial>
      <origin rpy="0 0 0" xyz="0.095348 0.011698 -0.001838"/>
      <mass value="0.57244"/>
      <inertia ixx="0.00030595" ixy="0.00035537" ixz="0.00011764" iyy="0.0032009" iyz="-1.129E-05" izz="0.0034209"/>
    </inertial>
    <visual>
      <origin rpy="0 0 0" xyz="0 0 0"/>
      <geometry>
        <mesh filename="file:///home/basanta-joshi/Desktop/virtual_environment/diablo_env_ros/install/diablo_env_ros/share/diablo_env_ros/meshes/right_leg_3.STL"/>
      </geometry>
      <material name="grey"/>
    </visual>
    <collision>
      <origin rpy="0 0 0" xyz="0.131 0 0"/>
      <geometry>
        <box size="0.2 0.07 0.05"/>
        <!-- <mesh filename="file://$(find diablo_env_ros)/meshes/right_leg_3.STL" /> -->
      </geometry>
    </collision>
  </link>
  <joint name="joint_right_leg_3" type="revolute">
    <origin rpy="0 0 0" xyz="0.2 0 0"/>
    <parent link="right_leg_2"/>
    <child link="right_leg_3"/>
    <axis xyz="0 0 1"/>
    <limit effort="100" lower="-2.670354" upper="-0.698132" velocity="100"/>
  </joint>
  <link name="right_leg_4">
    <inertial>
      <origin rpy="0 0 0" xyz="-2.3798E-06 -1.5854E-06 0.00095595"/>
      <mass value="1.5094"/>
      <inertia ixx="0.0035465" ixy="7.0548E-06" ixz="2.3146E-07" iyy="0.0035052" iyz="1.9287E-08" izz="0.0069047"/>
    </inertial>
    <visual>
      <origin rpy="0 0 0" xyz="0 0 0"/>
      <geometry>
        <box size="0.0925 0.0925 0.0925"/>
        <!-- <mesh filename="file://$(find diablo_env_ros)/meshes/right_leg_4.STL" /> -->
      </geometry>
      <material name="silver"/>
    </visual>
    <collision>
      <origin rpy="0 0 0" xyz="0 0 0"/>
      <geometry>
        <box size="0.0925 0.0925 0.0925"/>
        <!-- <cylinder length="0.034" radius="0.0925"/> -->
        <!-- <mesh filename="file://$(find diablo_env_ros)/meshes/right_leg_4.STL" /> -->
      </geometry>
    </collision>
  </link>
  <joint name="joint_right_leg_4" type="revolute">
    <origin rpy="0 0 0" xyz="0.2 0 -0.0514"/>
    <parent link="right_leg_3"/>
    <child link="right_leg_4"/>
    <axis xyz="0 0 1"/>
    <limit effort="100" lower="-6.283185e4" upper="6.283185e4" velocity="100"/>
  </joint>
  <!-- Gazebo Physics Properties -->
  <gazebo>
    <mu1>0.5</mu1>
    <!-- static friction coefficient -->
    <mu2>0.3</mu2>
    <!-- dynamic friction coefficient -->
  </gazebo>
  <!-- Enable Self-Collisions -->
  <gazebo reference="base_link">
    <self_collide>true</self_collide>
  </gazebo>
  <gazebo reference="left_leg_1">
    <self_collide>true</self_collide>
  </gazebo>
  <gazebo reference="left_leg_2">
    <self_collide>true</self_collide>
  </gazebo>
  <gazebo reference="left_leg_3">
    <self_collide>true</self_collide>
  </gazebo>
  <gazebo reference="left_leg_4">
    <self_collide>true</self_collide>
  </gazebo>
  <gazebo reference="right_leg_1">
    <self_collide>true</self_collide>
  </gazebo>
  <gazebo reference="right_leg_2">
    <self_collide>true</self_collide>
  </gazebo>
  <gazebo reference="right_leg_3">
    <self_collide>true</self_collide>
  </gazebo>
  <gazebo reference="right_leg_4">
    <self_collide>true</self_collide>
  </gazebo>
  <!-- Gazebo Plugins and Sensors -->
  <gazebo>
    <plugin filename="gz-sim-joint-controller-system" name="gz::sim::systems::JointController">
      <joint_name>joint_left_leg_1</joint_name>
      <topic>joint_left_leg_1_effort</topic>
      <use_force_commands>true</use_force_commands>
    </plugin>
    <plugin filename="gz-sim-joint-controller-system" name="gz::sim::systems::JointController">
      <joint_name>joint_right_leg_1</joint_name>
      <topic>joint_right_leg_1_effort</topic>
      <use_force_commands>true</use_force_commands>
    </plugin>
    <plugin filename="gz-sim-joint-controller-system" name="gz::sim::systems::JointController">
      <joint_name>joint_left_leg_2</joint_name>
      <topic>joint_left_leg_2_effort</topic>
      <use_force_commands>true</use_force_commands>
    </plugin>
    <plugin filename="gz-sim-joint-controller-system" name="gz::sim::systems::JointController">
      <joint_name>joint_right_leg_2</joint_name>
      <topic>joint_right_leg_2_effort</topic>
      <use_force_commands>true</use_force_commands>
    </plugin>
    <plugin filename="gz-sim-joint-controller-system" name="gz::sim::systems::JointController">
      <joint_name>joint_left_leg_3</joint_name>
      <topic>joint_left_leg_3_effort</topic>
      <use_force_commands>true</use_force_commands>
    </plugin>
    <plugin filename="gz-sim-joint-controller-system" name="gz::sim::systems::JointController">
      <joint_name>joint_right_leg_3</joint_name>
      <topic>joint_right_leg_3_effort</topic>
      <use_force_commands>true</use_force_commands>
    </plugin>
    <plugin filename="gz-sim-joint-controller-system" name="gz::sim::systems::JointController">
      <joint_name>joint_left_leg_4</joint_name>
      <topic>joint_left_leg_4_effort</topic>
      <use_force_commands>true</use_force_commands>
    </plugin>
    <plugin filename="gz-sim-joint-controller-system" name="gz::sim::systems::JointController">
      <joint_name>joint_right_leg_4</joint_name>
      <topic>joint_right_leg_4_effort</topic>
      <use_force_commands>true</use_force_commands>
    </plugin>
    <plugin filename="gz-sim-joint-state-publisher-system" name="gz::sim::systems::JointStatePublisher">
      <topic>joint_states</topic>
      <joint_name>joint_left_leg_1</joint_name>
      <joint_name>joint_right_leg_1</joint_name>
      <joint_name>joint_left_leg_2</joint_name>
      <joint_name>joint_right_leg_2</joint_name>
      <joint_name>joint_left_leg_3</joint_name>
      <joint_name>joint_right_leg_3</joint_name>
      <joint_name>joint_left_leg_4</joint_name>
      <joint_name>joint_right_leg_4</joint_name>
    </plugin>
  </gazebo>
  <gazebo reference="imu_link">
    <sensor name="imu" type="imu">
      <always_on>1</always_on>
      <update_rate>20</update_rate>
      <visualize>true</visualize>
      <topic>imu</topic>
      <enable_metrics>true</enable_metrics>
      <gz_frame_id>imu_link</gz_frame_id>
    </sensor>
  </gazebo>
  <gazebo reference="lidar_frame">
    <sensor name="gpu_lidar" type="gpu_lidar">
      &quot;
        
      <pose relative_to="lidar_frame">0 0 0 0 0 0</pose>
      <topic>lidar</topic>
      <gz_frame_id>lidar_frame</gz_frame_id>
      <update_rate>20</update_rate>
      <ray>
        <scan>
          <horizontal>
            <samples>3</samples>
            <resolution>1</resolution>
            <min_angle>-1.5708</min_angle>
            <max_angle>1.5708</max_angle>
          </horizontal>
        </scan>
        <range>
          <min>0.08</min>
          <max>10.0</max>
          <resolution>0.01</resolution>
        </range>
      </ray>
      <always_on>1</always_on>
      <visualize>true</visualize>
    </sensor>
  </gazebo>
</robot>
